yoshidzBookpuro:blog kei.$ python manage.py makemigrations
No changes detected
yoshidzBookpuro:blog kei.$ python manage.py makemigrations
Migrations for 'blog_app':
  blog_app/migrations/0001_initial.py
    - Create model Blog
    - Create model Comment
yoshidzBookpuro:blog kei.$ python manage.py migrate
Operations to perform:
  Apply all migrations: admin, auth, blog_app, contenttypes, sessions
Running migrations:
  Applying contenttypes.0001_initial... OK
  Applying auth.0001_initial... OK
  Applying admin.0001_initial... OK
  Applying admin.0002_logentry_remove_auto_add... OK
  Applying admin.0003_logentry_add_action_flag_choices... OK
  Applying admin.0004_auto_20181015_1032...Traceback (most recent call last):
  File "/Users/kei./anaconda3/lib/python3.6/site-packages/django/db/models/options.py", line 564, in get_field
    return self.fields_map[field_name]
KeyError: 'user_id'

During handling of the above exception, another exception occurred:

Traceback (most recent call last):
  File "manage.py", line 18, in <module>
    execute_from_command_line(sys.argv)
  File "/Users/kei./anaconda3/lib/python3.6/site-packages/django/core/management/__init__.py", line 381, in execute_from_command_line
    utility.execute()
  File "/Users/kei./anaconda3/lib/python3.6/site-packages/django/core/management/__init__.py", line 375, in execute
    self.fetch_command(subcommand).run_from_argv(self.argv)
  File "/Users/kei./anaconda3/lib/python3.6/site-packages/django/core/management/base.py", line 316, in run_from_argv
    self.execute(*args, **cmd_options)
  File "/Users/kei./anaconda3/lib/python3.6/site-packages/django/core/management/base.py", line 353, in execute
    output = self.handle(*args, **options)
  File "/Users/kei./anaconda3/lib/python3.6/site-packages/django/core/management/base.py", line 83, in wrapped
    res = handle_func(*args, **kwargs)
  File "/Users/kei./anaconda3/lib/python3.6/site-packages/django/core/management/commands/migrate.py", line 203, in handle
    fake_initial=fake_initial,
  File "/Users/kei./anaconda3/lib/python3.6/site-packages/django/db/migrations/executor.py", line 117, in migrate
    state = self._migrate_all_forwards(state, plan, full_plan, fake=fake, fake_initial=fake_initial)
  File "/Users/kei./anaconda3/lib/python3.6/site-packages/django/db/migrations/executor.py", line 147, in _migrate_all_forwards
    state = self.apply_migration(state, migration, fake=fake, fake_initial=fake_initial)
  File "/Users/kei./anaconda3/lib/python3.6/site-packages/django/db/migrations/executor.py", line 244, in apply_migration
    state = migration.apply(state, schema_editor)
  File "/Users/kei./anaconda3/lib/python3.6/site-packages/django/db/migrations/migration.py", line 124, in apply
    operation.database_forwards(self.app_label, schema_editor, old_state, project_state)
  File "/Users/kei./anaconda3/lib/python3.6/site-packages/django/db/migrations/operations/fields.py", line 216, in database_forwards
    schema_editor.alter_field(from_model, from_field, to_field)
  File "/Users/kei./anaconda3/lib/python3.6/site-packages/django/db/backends/base/schema.py", line 495, in alter_field
    new_db_params = new_field.db_parameters(connection=self.connection)
  File "/Users/kei./anaconda3/lib/python3.6/site-packages/django/db/models/fields/related.py", line 966, in db_parameters
    return {"type": self.db_type(connection), "check": self.db_check(connection)}
  File "/Users/kei./anaconda3/lib/python3.6/site-packages/django/db/models/fields/related.py", line 963, in db_type
    return self.target_field.rel_db_type(connection=connection)
  File "/Users/kei./anaconda3/lib/python3.6/site-packages/django/db/models/fields/related.py", line 878, in target_field
    return self.foreign_related_fields[0]
  File "/Users/kei./anaconda3/lib/python3.6/site-packages/django/db/models/fields/related.py", line 632, in foreign_related_fields
    return tuple(rhs_field for lhs_field, rhs_field in self.related_fields if rhs_field)
  File "/Users/kei./anaconda3/lib/python3.6/site-packages/django/db/models/fields/related.py", line 619, in related_fields
    self._related_fields = self.resolve_related_fields()
  File "/Users/kei./anaconda3/lib/python3.6/site-packages/django/db/models/fields/related.py", line 612, in resolve_related_fields
    else self.remote_field.model._meta.get_field(to_field_name))
  File "/Users/kei./anaconda3/lib/python3.6/site-packages/django/db/models/options.py", line 566, in get_field
    raise FieldDoesNotExist("%s has no field named '%s'" % (self.object_name, field_name))
django.core.exceptions.FieldDoesNotExist: User has no field named 'user_id'
yoshidzBookpuro:blog kei.$